Workbook

Sheet Sheet1
B1: Measurement Sheet
A3: Sr.No. | B3: Description | C3: No. | D3: L | E3: B | F3: H | G3: Unit | H3: Quantity
A5: A | B5: SALES OFFICE
A6: 1 | B6: Window Granite Frame
B7: For Pantry | C7: 2 | D7: 1.8 | G7: R.mtr | H7: =C7*D7 -> 3.6
C8: 2 | D8: 1.9 | G8: R.mtr | H8: =C8*D8 -> 3.8
C9: 2 | D9: 3.2 | G9: R.mtr | H9: =C9*D9 -> 6.4
C10: 2 | D10: 2.3 | G10: R.mtr | H10: =C10*D10 -> 4.6
B11: CEO 2 | C11: 2 | D11: 2.63 | G11: R.mtr | H11: =C11*D11 -> 5.26
C12: 2 | D12: 2.4 | G12: R.mtr | H12: =C12*D12 -> 4.8
B13: Acount department | C13: 2 | D13: 2.34 | G13: R.mtr | H13: =C13*D13 -> 4.68
C14: 2 | D14: 2.35 | G14: R.mtr | H14: =C14*D14 -> 4.7
B15: CEO 1 | C15: 2 | D15: 2.3 | G15: R.mtr | H15: =C15*D15 -> 4.6
C16: 2 | D16: 1.52 | G16: R.mtr | H16: =C16*D16 -> 3.04
B17: Rest room | C17: 2 | D17: 2.35 | G17: R.mtr | H17: =C17*D17 -> 4.7
C18: 2 | D18: 1.6 | G18: R.mtr | H18: =C18*D18 -> 3.2
C19: 2 | D19: 1.34 | G19: R.mtr | H19: =C19*D19 -> 2.68
C20: 2 | D20: 2.35 | G20: R.mtr | H20: =C20*D20 -> 4.7
B21: Toilet Ventilators | C21: 3 | D21: 0.88 | G21: R.mtr | H21: =C21*D21 -> 2.64
C22: 3 | D22: 0.59 | G22: R.mtr | H22: =C22*D22 -> 1.77
H23: =SUM(H7:H22) -> 65.17
G24: R.ft | H24: =H23*3.28 -> 213.7576
A26: 2 | B26: Door Granite Frame
B27: Toilet Door | C27: 3 | D27: 0.72 | G27: R.mtr | H27: =C27*D27 -> 2.16
C28: 6 | D28: 2.9 | G28: R.mtr | H28: =C28*D28 -> 17.4
B29: Porch | C29: 1 | D29: 1.5 | G29: R.mtr | H29: =C29*D29 -> 1.5
C30: 1 | D30: 1.525 | G30: R.mtr | H30: =C30*D30 -> 1.525
C31: 1 | D31: 4.33 | G31: R.mtr | H31: =C31*D31 -> 4.33
B32: CEO 2 Umbra patti | C32: 1 | D32: 1.2 | G32: R.mtr | H32: =C32*D32 -> 1.2
C33: 1 | D33: 0.9 | G33: R.mtr | H33: =C33*D33 -> 0.9
B34: CEO 1 Umbra patti | C34: 1 | D34: 1 | G34: R.mtr | H34: =C34*D34 -> 1
B35: Restroom | C35: 1 | D35: 0.9 | G35: R.mtr | H35: =C35*D35 -> 0.9
B36: Toilet Umbra patti | C36: 3 | D36: 0.65 | G36: R.mtr | H36: =C36*D36 -> 1.95
B37: A. V. room | C37: 1 | D37: 1.17 | G37: R.mtr | H37: =C37*D37 -> 1.17
H38: =SUM(H27:H37) -> 34.035
G39: R.ft | H39: =H38*3.28 -> 111.6348
A41: 3 | B41: Edge polish | C41: 1 | D41: =H23 -> 65.17 | G41: R.mtr | H41: =C41*D41 -> 65.17
C42: 1 | D42: =H38 -> 34.035 | G42: R.mtr | H42: =C42*D42 -> 34.035
H43: =SUM(H41:H42) -> 99.205
G44: R.ft | H44: =H43*3.28 -> 325.3924
...

Sheet Sheet2
A2: Summary Sheet
A4: Sr.No. | B4: Description of work | C4: Quantity | D4: Unit | E4: Rate | F4: Amount
A6: 1 | B6: =Sheet1!B6 -> Window Granite Frame | C6: =Sheet1!H24+Sheet1!H102 -> 296.9712 | D6: =Sheet1!G24 -> R.ft | E6: 60 | F6: =C6*E6 -> 17818.272
A7: 2 | B7: =Sheet1!B26 -> Door Granite Frame | C7: =Sheet1!H39+Sheet1!H108 -> 166.2468 | D7: =Sheet1!G39 -> R.ft | E7: 135 | F7: =C7*E7 -> 22443.318
A8: 3 | B8: Kitchen Vertical | C8: 3 | D8: Nos. | E8: 1200 | F8: =C8*E8 -> 3600
A9: 4 | B9: =Sheet1!B46 -> Kitchen Platform | C9: 34.7 | D9: =Sheet1!G47 -> R.ft | E9: 600 | F9: =C9*E9 -> 20820
A10: 5 | B10: Dado Tile 600x600 | C10: =Sheet1!H58 -> 557.57143 | D10: =Sheet1!G58 -> Sq.ft | E10: 32 | F10: =C10*E10 -> 17842.286
A11: 6 | B11: Dado Tile 600x1200 | C11: =Sheet1!H136 -> 564.94854 | D11: Sq.ft | E11: 32 | F11: =C11*E11 -> 18078.353
A12: 7 | B12: Toilet Flooring 600x1200 | C12: =Sheet1!H144 -> 99.217977 | D12: Sq.ft | E12: 30 | F12: =C12*E12 -> 2976.5393
A13: 8 | B13: Toilet Flooring 300x300 | C13: =Sheet1!H63 -> 82.72134 | D13: =Sheet1!G63 -> Sq.ft | E13: 25 | F13: =C13*E13 -> 2068.0335
A14: 9 | B14: Flooring 800x800 | C14: =Sheet1!H83 -> 2161.7275 | D14: =Sheet1!G83 -> Sq.ft | E14: 30 | F14: =C14*E14 -> 64851.826
A15: 10 | B15: Flooring 600x1200 | C15: =Sheet1!H167 -> 1014.6924 | D15: Sq.ft | E15: 30 | F15: =C15*E15 -> 30440.772
A16: 11 | B16: Skirting 800x800 | C16: =Sheet1!H87 -> 442.8656 | D16: =Sheet1!G87 -> R.ft | E16: 30 | F16: =C16*E16 -> 13285.968
A17: 12 | B17: Skirting 600x1200 | C17: =Sheet1!H180 -> 292.7892 | D17: R.ft | E17: 30 | F17: =C17*E17 -> 8783.676
A18: 13 | B18: Basin counter | C18: 7 | D18: No. | E18: 1200 | F18: =C18*E18 -> 8400
D19: Total Amount = | F19: =SUM(F6:F18) -> 231409.04
